Workbook

Sheet BDAssetHealthStatus
A1: Row Status | B1: Name | C1: PSCMMSID | E1: ID
A2: ({0:No Change},{1: New},{2: Update}) | B2: Name | C2: Functions Id ( AHST ) | E2: ID
A3: 0 | B3: تحت مراقبت | C3: AHST1 | E3: 0bbc3495-6628-4343-9fd6-11e7b15666f9
A4: 0 | B4: نیاز به مراقبت | C4: AHST2 | E4: c8c66ebf-585d-402a-914c-406d5744bb5a
A5: 0 | B5: سالم | C5: AHST3 | E5: da855c55-b5fa-4669-8a8d-7460161d8a97
A6: 0 | B6: در حال خرابی | C6: AHST4 | E6: eca9754a-cea5-42ae-8685-bfea06f1d4df

Sheet AssetCriticality
A1: Row Status | B1: Name | C1: PSCMMSID | E1: ID
A2: ({0:No Change},{1: New},{2: Update}) | B2: Criticality Name | C2: Criticality Id ( AsCr ) | E2: ID
A3: 0 | B3: VITAL | C3: AsCr1 | E3: 826ffe9c-3d05-4756-b346-3efcbf19c0a4
A4: 0 | B4: خیلی کم | C4: AsCr2 | E4: ab5f22a7-700b-46e9-8eaf-b40fdc262e7b
A5: 0 | B5: IMPORTANT | C5: AsCr3 | E5: edb11437-78cc-4a9e-a51d-b9ef2634059b
A6: 0 | B6: NORMAL | C6: AsCr4 | E6: fc73e532-6b8f-47c7-864d-bb26af7ffe51
A7: 0 | B7: ESSENTIAL | C7: AsCr5 | E7: 9e40e9bc-b740-4c57-82e8-fe13878bb23c

Sheet AssetClass
A1: Row Status | B1: Name | C1: PSCMMSID | D1: CODE | E1: Notes | G1: ID
A2: ({0:No Change},{1: New},{2: Update}) | B2: Asset Class Name | C2: Asset Class Id ( ASCL ) | D2: Asset Class Code | E2: Notes | G2: ID
A3: 0 | B3: Blowers | C3: ASCL1 | D3: BL | G3: 432177b5-b1aa-4d11-b53c-58cb6c12ad9a
A4: 0 | B4: Fans | C4: ASCL2 | D4: FN | G4: 468b0eb6-a5c3-40b2-b212-e8858be43756
A5: 0 | B5: Compressors | C5: ASCL3 | D5: CO | G5: b1a7d55b-e02c-432d-8ef8-9fb2a58a3387
A6: 0 | B6: Pumps | C6: ASCL4 | D6: PU | G6: 06468d59-1f5d-481d-a40a-253278257888
A7: 0 | B7: Cryogenic Pumps | C7: ASCL5 | D7: PC | G7: 947da44b-6ef4-479e-a583-22c4d5f5775c
A8: 0 | B8: Electric Motors | C8: ASCL6 | D8: EM | G8: 59fa8c33-838e-427e-ae47-7cf309d549d8
A9: 0 | B9: Combustion Engines | C9: ASCL7 | D9: CE | G9: 234ebdf1-0e17-4c5a-84c3-3480161afa20
A10: 0 | B10: Mixers | C10: ASCL8 | D10: MI | G10: ad9f436a-e979-4f4e-b68d-8b5969406542
A11: 0 | B11: Turbo expanders | C11: ASCL9 | D11: TE | G11: 6734f63e-6bbb-4236-8175-c73fcfb56ff2
A12: 0 | B12: Flow Dividers | C12: ASCL10 | D12: FL | G12: ec7f11e4-a884-4b4d-ab32-54020fa11665
A13: 0 | B13: Hydromotor | C13: ASCL11 | D13: HM | G13: 5cd56e56-2206-4062-9c42-dd17d4a17e60
A14: 0 | B14: Transmission | C14: ASCL12 | D14: TM | G14: 3e4614b6-93db-40ab-bbd8-4521c246710d
... A73: 0 | B73: Emergency | C73: ASCL71 | D73: EC | G73: 9d47110a-467c-416e-8ae0-9ade55b5efce

Sheet Locations
A1: Row Status | B1: Name | C1: PSCMMSID | D1: Code | E1: Locations_PSCMMSID | F1: ParentLocationsName | G1: Org_PSCMMSID | H1: OrgName | J1: ID
A2: ({0:No Change},{1: New},{2: Update}) | B2: Locations | C2: Locations Id ( LC ) | D2: Locations Code | E2: Locations Id | F2: ParentLocationsName | G2: Org Id | H2: OrgName | J2: ID
A3: 0 | B3: Chadormalu Industrial Company | C3: LC2 | D3: CHIC | E3: =VLOOKUP(F3,B:C,2,0) -> #N/A | G3: =VLOOKUP(H3,Organization!B:C,2,0) -> #N/A | J3: 62acd369-7dd1-4bb6-b687-272ccfeb9403
A4: 0 | B4: Pelletizing Plant | C4: LC3 | D4: Pelletizing | E4: =VLOOKUP(F4,B:C,2,0) -> LC2 | F4: Chadormalu Industrial Company | G4: =VLOOKUP(H4,Organization!B:C,2,0) -> BDC4 | H4: گندله سازي | J4: 8ed8a31b-c9b4-4a65-b3be-2ce2e03bd65e
A5: 0 | B5: Concentrate Receiving, Stockpiling & Reclaiming | C5: LC5 | D5: 0100 | E5: =VLOOKUP(F5,B:C,2,0) -> LC3 | F5: Pelletizing Plant | G5: =VLOOKUP(H5,Organization!B:C,2,0) -> BDC4 | H5: گندله سازي | J5: 06f279f6-a75f-485e-88b0-8ad3fed413e2
A6: 0 | B6: Limestone Drying & Grinding | C6: LC6 | D6: 0200 | E6: =VLOOKUP(F6,B:C,2,0) -> LC3 | F6: Pelletizing Plant | G6: =VLOOKUP(H6,Organization!B:C,2,0) -> BDC4 | H6: گندله سازي | J6: 9bd79315-3cad-497a-b6a1-a065dcf69d3b
A7: 0 | B7: Bentonite Receiving | C7: LC7 | D7: 0300 | E7: =VLOOKUP(F7,B:C,2,0) -> LC3 | F7: Pelletizing Plant | G7: =VLOOKUP(H7,Organization!B:C,2,0) -> BDC4 | H7: گندله سازي | J7: cc3d0a49-7d1c-41bd-bc06-fd646c465de4
A8: 0 | B8: Mixing Area | C8: LC8 | D8: 0500 | E8: =VLOOKUP(F8,B:C,2,0) -> LC3 | F8: Pelletizing Plant | G8: =VLOOKUP(H8,Organization!B:C,2,0) -> BDC4 | H8: گندله سازي | J8: 400a93c4-8ea8-4e53-9130-805d0961e4a0
A9: 0 | B9: Balling | C9: LC9 | D9: 0600 | E9: =VLOOKUP(F9,B:C,2,0) -> LC3 | F9: Pelletizing Plant | G9: =VLOOKUP(H9,Organization!B:C,2,0) -> BDC4 | H9: گندله سازي | J9: 6c110522-0818-427a-80ba-9b536a704d0c
A10: 0 | B10: Induration | C10: LC10 | D10: 0700 | E10: =VLOOKUP(F10,B:C,2,0) -> LC3 | F10: Pelletizing Plant | G10: =VLOOKUP(H10,Organization!B:C,2,0) -> BDC4 | H10: گندله سازي | J10: 201326b5-ace5-42ba-9604-dc1485d0b079
A11: 0 | B11: Product Stockpilling, Reclaiming & Load-out | C11: LC11 | D11: 0800 | E11: =VLOOKUP(F11,B:C,2,0) -> LC3 | F11: Pelletizing Plant | G11: =VLOOKUP(H11,Organization!B:C,2,0) -> BDC4 | H11: گندله سازي | J11: 297b05ad-e570-4155-a378-f683ab584dd4
A12: 0 | B12: Waste Reclamation | C12: LC12 | D12: 0900 | E12: =VLOOKUP(F12,B:C,2,0) -> LC3 | F12: Pelletizing Plant | G12: =VLOOKUP(H12,Organization!B:C,2,0) -> BDC4 | H12: گندله سازي | J12: 1191fd22-b66b-4bb9-8cf8-13d256c15156
A13: 0 | B13: Crane & Hoist | C13: LC13 | D13: 1000 | E13: =VLOOKUP(F13,B:C,2,0) -> LC3 | F13: Pelletizing Plant | G13: =VLOOKUP(H13,Organization!B:C,2,0) -> BDC4 | H13: گندله سازي | J13: a380b63a-fd1c-4546-a87f-b5861e7d10bd
A14: 0 | B14: Laboratory Equipment | C14: LC14 | D14: 1100 | E14: =VLOOKUP(F14,B:C,2,0) -> LC3 | F14: Pelletizing Plant | G14: =VLOOKUP(H14,Organization!B:C,2,0) -> BDC4 | H14: گندله سازي | J14: c1938466-591b-44c0-b061-68f6004f18f9
A15: 0 | B15: Machine Shop Equipment | C15: LC15 | D15: 1200 | E15: =VLOOKUP(F15,B:C,2,0) -> LC3 | F15: Pelletizing Plant | G15: =VLOOKUP(H15,Organization!B:C,2,0) -> BDC4 | H15: گندله سازي | J15: 15d24ac6-df8b-425c-acf4-185c188f15d3
... A89: 0 | B89: Transport | C89: LC89 | D89: C450 | E89: =VLOOKUP(F89,B:C,2,0) -> LC22 | F89: Ancillary Building | G89: =VLOOKUP(H89,Organization!B:C,2,0) -> BDC4 | H89: گندله سازي | J89: d1908180-9f9b-4758-ad05-45e9cbf3d564

Sheet AssetCategory
A1: Row Status | B1: FullCategoryName | C1: PSCMMSID | D1: Name | E1: CODE | F1: ClassID_PSCMMSID | G1: ClassName | H1: Manufacturer | I1: Model | K1: ID
A2: ({0:No Change},{1: New},{2: Update}) | B2: Asset Category ّFull NAme | C2: Asset Category Id ( ASCA ) | D2: Asset Category Name | E2: Asset Category Code | F2: Asset Class Id | G2: ClassName | H2: Manufacturer | I2: Model | K2: ID
A3: 0 | B3: Centrifugal-Blowers | C3: ASCA1 | D3: Centrifugal | E3: CE | F3: =VLOOKUP(G3,AssetClass!B:C,2,0) -> ASCL1 | G3: Blowers | K3: ff12e9b1-9f63-46e7-9223-e8b3c0372665
A4: 0 | B4: Axial-Blowers | C4: ASCA2 | D4: Axial | E4: AX | F4: =VLOOKUP(G4,AssetClass!B:C,2,0) -> ASCL1 | G4: Blowers | K4: 1f3088a2-f238-4b3c-ac66-8c121a4ba341
A5: 0 | B5: Lobe-Blowers | C5: ASCA3 | D5: Lobe | E5: LO | F5: =VLOOKUP(G5,AssetClass!B:C,2,0) -> ASCL1 | G5: Blowers | K5: 747ff2eb-54c8-4345-ae74-6806b783d537
A6: 0 | B6: Screw-Blowers | C6: ASCA4 | D6: Screw | E6: SC | F6: =VLOOKUP(G6,AssetClass!B:C,2,0) -> ASCL1 | G6: Blowers | K6: 081cd4a6-b330-4e76-9ebf-d8331f5d63bd
A7: 0 | B7: Centrifugal-Fans | C7: ASCA5 | D7: Centrifugal | E7: CE | F7: =VLOOKUP(G7,AssetClass!B:C,2,0) -> ASCL2 | G7: Fans | K7: a3fae316-6f4d-4905-befa-3912c30ef013
A8: 0 | B8: Axial-Fans | C8: ASCA6 | D8: Axial | E8: AX | F8: =VLOOKUP(G8,AssetClass!B:C,2,0) -> ASCL2 | G8: Fans | K8: 5e2f6d2f-e2f3-4bad-9096-4c37b3dbd505
A9: 0 | B9: Centrifugal-Compressors | C9: ASCA7 | D9: Centrifugal | E9: CE | F9: =VLOOKUP(G9,AssetClass!B:C,2,0) -> ASCL3 | G9: Compressors | K9: 7ac684c4-7977-481e-a1ea-e7565753b999
A10: 0 | B10: Reciprocating-Compressors | C10: ASCA8 | D10: Reciprocating | E10: RE | F10: =VLOOKUP(G10,AssetClass!B:C,2,0) -> ASCL3 | G10: Compressors | K10: 4815077b-7547-49c1-8c08-e1007c84c81d
A11: 0 | B11: Screw-Compressors | C11: ASCA9 | D11: Screw | E11: SC | F11: =VLOOKUP(G11,AssetClass!B:C,2,0) -> ASCL3 | G11: Compressors | K11: fab87bf9-ccb6-4b62-abef-d3c565d1ed91
A12: 0 | B12: Axial-Compressors | C12: ASCA10 | D12: Axial | E12: AX | F12: =VLOOKUP(G12,AssetClass!B:C,2,0) -> ASCL3 | G12: Compressors | K12: dcc3c5d0-fe27-40db-aeba-1a076f7649ca
A13: 0 | B13: Lobe-Compressors | C13: ASCA11 | D13: Lobe | E13: LO | F13: =VLOOKUP(G13,AssetClass!B:C,2,0) -> ASCL3 | G13: Compressors | K13: 048c1ab9-bd5f-4e4e-8d5d-c3334edaffaa
A14: 0 | B14: Centrifugal-Pumps | C14: ASCA12 | D14: Centrifugal | E14: CE | F14: =VLOOKUP(G14,AssetClass!B:C,2,0) -> ASCL4 | G14: Pumps | K14: 0f02a4b0-9ec0-4de7-a874-aa7bbaf1b802
... A87: 0 | B87: Direct Fired Heater-Heaters and Boilers | C87: ASCA85 | D87: Direct Fired Heater | E87: DF | F87: =VLOOKUP(G87,AssetClass!B:C,2,0) -> ASCL26 | G87: Heaters and Boilers | K87: 39db36ce-6a3f-400c-b5ef-5e4631839df3
A88: 0 | B88: Electric Heater-Heaters and Boilers | C88: ASCA86 | D88: Electric Heater | F88: =VLOOKUP(G88,AssetClass!B:C,2,0) -> ASCL26 | G88: Heaters and Boilers | K88: 606a608c-aa4d-4e8c-94b0-919f40c60a9a
A89: 0 | B89: Cooling Tower-Heat Exchangers | C89: ASCA87 | D89: Cooling Tower | E89: EC | F89: =VLOOKUP(G89,AssetClass!B:C,2,0) -> ASCL27 | G89: Heat Exchangers | K89: 0ba42247-0568-4703-a41b-3b7f839899d1
A90: 0 | B90: Shell And Tube-Heat Exchangers | C90: ASCA88 | D90: Shell And Tube | E90: ST | F90: =VLOOKUP(G90,AssetClass!B:C,2,0) -> ASCL27 | G90: Heat Exchangers | K90: fe0361cb-79bd-4bd0-b046-06fd273101b2
A91: 0 | B91: Plate-Heat Exchangers | C91: ASCA89 | D91: Plate | E91: PL | F91: =VLOOKUP(G91,AssetClass!B:C,2,0) -> ASCL27 | G91: Heat Exchangers | K91: 9a52ee73-009c-48a5-af20-46bf19861638
A92: 0 | B92: Air-Cooled-Heat Exchangers | C92: ASCA90 | D92: Air-Cooled | E92: AC | F92: =VLOOKUP(G92,AssetClass!B:C,2,0) -> ASCL27 | G92: Heat Exchangers | K92: 873c88e2-9425-4d33-873b-c0b5261ccba4
A93: 0 | B93: Hybrid Tower-Heat Exchangers | C93: ASCA91 | D93: Hybrid Tower | E93: HT | F93: =VLOOKUP(G93,AssetClass!B:C,2,0) -> ASCL27 | G93: Heat Exchangers | K93: 36e34a4a-a498-4e0e-bdf1-f4285ddbddbb
A94: 0 | B94: Balling Disk-Green Ball | C94: ASCA92 | D94: Balling Disk | E94: PE | F94: =VLOOKUP(G94,AssetClass!B:C,2,0) -> ASCL28 | G94: Green Ball | K94: 6f394062-267d-479b-bf94-12ad6282a207
A95: 0 | B95: Electric Hoist-Cranes | C95: ASCA93 | D95: Electric Hoist | E95: EH | F95: =VLOOKUP(G95,AssetClass!B:C,2,0) -> ASCL29 | G95: Cranes | K95: 5c837c2b-566a-42cf-928b-dc2911ad3916
A96: 0 | B96: Overhead Crane-Cranes | C96: ASCA94 | D96: Overhead Crane | E96: CA | F96: =VLOOKUP(G96,AssetClass!B:C,2,0) -> ASCL29 | G96: Cranes | K96: 7673fa19-cf5c-4b5e-be87-27dc58423175
A97: 0 | B97: Jib Crane-Cranes | C97: ASCA95 | D97: Jib Crane | E97: DO | F97: =VLOOKUP(G97,AssetClass!B:C,2,0) -> ASCL29 | G97: Cranes | K97: 510ccca6-3da5-42e5-9dd0-5e9f5a1c4f1c
A98: 0 | B98: Electric Winch-Winches | C98: ASCA96 | D98: Electric Winch | E98: EW | F98: =VLOOKUP(G98,AssetClass!B:C,2,0) -> ASCL30 | G98: Winches | K98: c10a5209-5c10-4d94-96e2-7d0697993ac4
A99: 0 | B99: Hydraulic Winch-Winches | C99: ASCA97 | D99: Hydraulic Winch | E99: HW | F99: =VLOOKUP(G99,AssetClass!B:C,2,0) -> ASCL30 | G99: Winches | K99: dba6a0c1-ad0f-428a-8cd2-4c3e227dd1b8
A100: 0 | B100: Vibrating Feeder-Feeder | C100: ASCA98 | D100: Vibrating Feeder | E100: VF | F100: =VLOOKUP(G100,AssetClass!B:C,2,0) -> ASCL31 | G100: Feeder | K100: 5fabdae5-0be2-4e36-bd64-8de5a64b5d56
... A113: 0 | B113: Silencer-Duct | C113: ASCA111 | D113: Silencer | E113: SI | F113: =VLOOKUP(G113,AssetClass!B:C,2,0) -> ASCL33 | G113: Duct | K113: e5d65409-c1be-49b8-a92b-5d7fa031f30b
A114: 0 | B114: Expansion Joint-Expansion Joint | C114: ASCA112 | D114: Expansion Joint | F114: =VLOOKUP(G114,AssetClass!B:C,2,0) -> ASCL34 | G114: Expansion Joint | K114: 1b32b0ba-2c4e-4279-a768-024b40aef6c1
A115: 0 | B115: Separator-Pressure Vessel | C115: ASCA113 | D115: Separator | E115: SE | F115: =VLOOKUP(G115,AssetClass!B:C,2,0) -> ASCL35 | G115: Pressure Vessel | K115: 7700dc52-cdf6-4982-81b7-c4de0796023a
A116: 0 | B116: Scrubber-Pressure Vessel | C116: ASCA114 | D116: Scrubber | E116: SB | F116: =VLOOKUP(G116,AssetClass!B:C,2,0) -> ASCL35 | G116: Pressure Vessel | K116: 45c39a3d-41a4-4a6b-96d6-33dfa424d820
A117: 0 | B117: Dryer-Pressure Vessel | C117: ASCA115 | D117: Dryer | E117: DR | F117: =VLOOKUP(G117,AssetClass!B:C,2,0) -> ASCL35 | G117: Pressure Vessel | K117: f20ccd57-3b78-4405-a366-7bb739aa21de
A118: 0 | B118: Chemical Reactor-Pressure Vessel | C118: ASCA116 | D118: Chemical Reactor | E118: CR | F118: =VLOOKUP(G118,AssetClass!B:C,2,0) -> ASCL35 | G118: Pressure Vessel | K118: 9f1ecc8b-c45b-41e8-8e90-0720cc5422be
A119: 0 | B119: Proportional Hopper-Pressure Vessel | C119: ASCA117 | D119: Proportional Hopper | E119: PH | F119: =VLOOKUP(G119,AssetClass!B:C,2,0) -> ASCL35 | G119: Pressure Vessel | K119: 522d8d4b-32e8-4316-a4c5-f2fb6856d147
A120: 0 | B120: Water Softener-Pressure Vessel | C120: ASCA118 | D120: Water Softener | E120: WS | F120: =VLOOKUP(G120,AssetClass!B:C,2,0) -> ASCL35 | G120: Pressure Vessel | K120: cb00811b-0481-4be1-8074-1810c66d5a7e
A121: 0 | B121: Storage Tank-Pressure Vessel | C121: ASCA119 | D121: Storage Tank | E121: ST | F121: =VLOOKUP(G121,AssetClass!B:C,2,0) -> ASCL35 | G121: Pressure Vessel | K121: 6ff62191-5030-46c4-8c39-f80754738ca4
A122: 0 | B122: Lime Coating-Coating Unit | C122: ASCA120 | D122: Lime Coating | E122: LC | F122: =VLOOKUP(G122,AssetClass!B:C,2,0) -> ASCL36 | G122: Coating Unit | K122: 46bb8e2a-bef8-42f2-985d-943ec5b922af
A123: 0 | B123: Bladder Accumulator-Damping Equipment | C123: ASCA121 | D123: Bladder Accumulator | E123: BA | F123: =VLOOKUP(G123,AssetClass!B:C,2,0) -> ASCL37 | G123: Damping Equipment | K123: 03180e93-001d-4442-a43c-bdf2472174e2
A124: 0 | B124: Piston Accumulator-Damping Equipment | C124: ASCA122 | D124: Piston Accumulator | E124: PA | F124: =VLOOKUP(G124,AssetClass!B:C,2,0) -> ASCL37 | G124: Damping Equipment | K124: aa4f6e53-1f01-47b1-8a82-371ee682a14a
...

Sheet Organization
A1: Row Status | B1: Nam | C1: PSCMMSID | D1: CODE | E1: ISACTIVE | F1: MasterOrg | G1: Org_PSCMMSID | H1: ParentOrg | I1: Locations_PSCMMSID | J1: LocationsName | K1: MasterORG_PSCMMSID | L1: MasterORGName | N1: ID
A2: ({0:No Change},{1: New},{2: Update}) | B2: Organization Name | C2: Organization ( BDC ) | D2: Organization Code | E2: IS ACTIVE? | F2: Is Master Org? | G2: ParentOrg Id | H2: ParentOrg | I2: Parent Location Id | J2: LocationsName | K2: MasterORG Id | L2: MasterORGName | N2: ID
A3: 0 | B3: مجتمع صنعتي معدني چادرملو | C3: BDC2 | D3: 001 | E3: False | F3: True | G3: =VLOOKUP(H3,B:C,2,0) -> #N/A | I3: =VLOOKUP(J3,Locations!B:C,2,0) -> #N/A | K3: =VLOOKUP(L3,B:C,2,0) -> BDC2 | L3: مجتمع صنعتي معدني چادرملو | N3: d692c763-2385-4fb9-9b50-3bf9afdfdcd1
A4: 0 | B4: گندله سازي | C4: BDC4 | D4: Pelletizing | E4: True | F4: True | G4: =VLOOKUP(H4,B:C,2,0) -> BDC2 | H4: مجتمع صنعتي معدني چادرملو | I4: =VLOOKUP(J4,Locations!B:C,2,0) -> #N/A | K4: =VLOOKUP(L4,B:C,2,0) -> BDC4 | L4: گندله سازي | N4: 7fb35690-37e7-4e6e-bda0-ea89cd8e03df
A5: 0 | B5: پاميدکو (بهره برداري) | C5: BDC5 | D5: 002 | E5: True | G5: =VLOOKUP(H5,B:C,2,0) -> BDC4 | H5: گندله سازي | I5: =VLOOKUP(J5,Locations!B:C,2,0) -> #N/A | K5: =VLOOKUP(L5,B:C,2,0) -> BDC5 | L5: پاميدکو (بهره برداري) | N5: 6b4e6a3b-f408-4f8b-863b-d621f19ec1a3
A6: 0 | B6: نظارت | C6: BDC6 | D6: 003 | E6: True | F6: False | G6: =VLOOKUP(H6,B:C,2,0) -> BDC4 | H6: گندله سازي | I6: =VLOOKUP(J6,Locations!B:C,2,0) -> #N/A | K6: =VLOOKUP(L6,B:C,2,0) -> BDC6 | L6: نظارت | N6: e2f5fd3f-cedf-47b5-9106-bae06370871f
A7: 0 | B7: کارفرما | C7: BDC7 | D7: 004 | E7: True | F7: False | G7: =VLOOKUP(H7,B:C,2,0) -> BDC4 | H7: گندله سازي | I7: =VLOOKUP(J7,Locations!B:C,2,0) -> #N/A | K7: =VLOOKUP(L7,B:C,2,0) -> BDC7 | L7: کارفرما | N7: 495542c2-7843-4059-ad6e-8820d58258ed
A8: 0 | B8: توليد | C8: BDC8 | D8: 005 | E8: True | G8: =VLOOKUP(H8,B:C,2,0) -> BDC5 | H8: پاميدکو (بهره برداري) | I8: =VLOOKUP(J8,Locations!B:C,2,0) -> #N/A | K8: =VLOOKUP(L8,B:C,2,0) -> BDC8 | L8: توليد | N8: efd0d3e2-6115-4957-9fd8-c5e69963c7e5
A9: 0 | B9: تعميرات مکانيک و تاسيسات | C9: BDC9 | D9: 006 | E9: True | F9: False | G9: =VLOOKUP(H9,B:C,2,0) -> BDC5 | H9: پاميدکو (بهره برداري) | I9: =VLOOKUP(J9,Locations!B:C,2,0) -> #N/A | K9: =VLOOKUP(L9,B:C,2,0) -> BDC9 | L9: تعميرات مکانيک و تاسيسات | N9: 3d37d7c0-4824-4ce5-b8d4-cd67dcde1f75
A10: 0 | B10: تعميرات برق و ابزار دقيق | C10: BDC10 | D10: 007 | E10: True | F10: False | G10: =VLOOKUP(H10,B:C,2,0) -> BDC5 | H10: پاميدکو (بهره برداري) | I10: =VLOOKUP(J10,Locations!B:C,2,0) -> #N/A | K10: =VLOOKUP(L10,B:C,2,0) -> BDC10 | L10: تعميرات برق و ابزار دقيق | N10: b34c1f71-1a6f-4cfd-ab25-e0fa9b3a2b46
A11: 0 | B11: کنترل فرآيند و کيفيت | C11: BDC11 | D11: 008 | E11: True | F11: False | G11: =VLOOKUP(H11,B:C,2,0) -> BDC5 | H11: پاميدکو (بهره برداري) | I11: =VLOOKUP(J11,Locations!B:C,2,0) -> #N/A | K11: =VLOOKUP(L11,B:C,2,0) -> BDC11 | L11: کنترل فرآيند و کيفيت | N11: b3ce3939-e319-4d67-99b0-3b6d2d18d0ca
A12: 0 | B12: ايمني و بهداشت | C12: BDC12 | D12: 009 | E12: True | G12: =VLOOKUP(H12,B:C,2,0) -> BDC5 | H12: پاميدکو (بهره برداري) | I12: =VLOOKUP(J12,Locations!B:C,2,0) -> #N/A | K12: =VLOOKUP(L12,B:C,2,0) -> BDC12 | L12: ايمني و بهداشت | N12: f54764c7-1837-489a-ac3e-f6296a459fe6
A13: 0 | B13: منابع انساني و امور مالي | C13: BDC13 | D13: 010 | E13: True | G13: =VLOOKUP(H13,B:C,2,0) -> BDC5 | H13: پاميدکو (بهره برداري) | I13: =VLOOKUP(J13,Locations!B:C,2,0) -> #N/A | K13: =VLOOKUP(L13,B:C,2,0) -> BDC13 | L13: منابع انساني و امور مالي | N13: 5d1d6c76-c547-4166-a028-9dd008d92d83
A14: 0 | B14: بازرگاني | C14: BDC14 | D14: 011 | E14: True | G14: =VLOOKUP(H14,B:C,2,0) -> BDC5 | H14: پاميدکو (بهره برداري) | I14: =VLOOKUP(J14,Locations!B:C,2,0) -> #N/A | K14: =VLOOKUP(L14,B:C,2,0) -> BDC14 | L14: بازرگاني | N14: d8078972-96f0-4d41-9f34-8a88b5dd4702
A15: 0 | B15: انتظامات | C15: BDC15 | D15: 012 | E15: True | G15: =VLOOKUP(H15,B:C,2,0) -> BDC5 | H15: پاميدکو (بهره برداري) | I15: =VLOOKUP(J15,Locations!B:C,2,0) -> #N/A | K15: =VLOOKUP(L15,B:C,2,0) -> BDC15 | L15: انتظامات | N15: 094bfc69-410a-4f4f-b521-98821fd0cd97
A16: 0 | B16: سفارشات | C16: BDC16 | D16: 013 | E16: True | G16: =VLOOKUP(H16,B:C,2,0) -> BDC5 | H16: پاميدکو (بهره برداري) | I16: =VLOOKUP(J16,Locations!B:C,2,0) -> #N/A | K16: =VLOOKUP(L16,B:C,2,0) -> BDC16 | L16: سفارشات | N16: 7c8ef912-0a11-4df4-8dca-687dea9155e1
A17: 0 | B17: انبار | C17: BDC17 | D17: 014 | E17: True | G17: =VLOOKUP(H17,B:C,2,0) -> BDC5 | H17: پاميدکو (بهره برداري) | I17: =VLOOKUP(J17,Locations!B:C,2,0) -> #N/A | K17: =VLOOKUP(L17,B:C,2,0) -> BDC17 | L17: انبار | N17: b8fd8f71-2e93-40cf-8a5c-ccf508b23d8c
A18: 0 | B18: پشتيباني و خدمات | C18: BDC18 | D18: 015 | E18: True | G18: =VLOOKUP(H18,B:C,2,0) -> BDC5 | H18: پاميدکو (بهره برداري) | I18: =VLOOKUP(J18,Locations!B:C,2,0) -> #N/A | K18: =VLOOKUP(L18,B:C,2,0) -> BDC18 | L18: پشتيباني و خدمات | N18: 51f333b4-58e8-4b50-9d22-031a4d5da019
A19: 0 | B19: زرپي جوش (پيمانکار) | C19: BDC19 | D19: 016 | E19: True | F19: False | G19: =VLOOKUP(H19,B:C,2,0) -> BDC9 | H19: تعميرات مکانيک و تاسيسات | I19: =VLOOKUP(J19,Locations!B:C,2,0) -> #N/A | K19: =VLOOKUP(L19,B:C,2,0) -> BDC19 | L19: زرپي جوش (پيمانکار) | N19: 425af2fb-bc0e-4dd2-8ab1-35e5df953cbd
A20: 0 | B20: مفتاح صنعت (پيمانکار) | C20: BDC20 | D20: 017 | E20: True | F20: False | G20: =VLOOKUP(H20,B:C,2,0) -> BDC9 | H20: تعميرات مکانيک و تاسيسات | I20: =VLOOKUP(J20,Locations!B:C,2,0) -> #N/A | K20: =VLOOKUP(L20,B:C,2,0) -> BDC20 | L20: مفتاح صنعت (پيمانکار) | N20: a586e718-dc1f-4c2a-b90c-07870e6aa798
A21: 0 | B21: پارس پويا صنعت (پيمانکار) | C21: BDC21 | D21: 018 | E21: True | F21: False | G21: =VLOOKUP(H21,B:C,2,0) -> BDC11 | H21: کنترل فرآيند و کيفيت | I21: =VLOOKUP(J21,Locations!B:C,2,0) -> #N/A | K21: =VLOOKUP(L21,B:C,2,0) -> BDC21 | L21: پارس پويا صنعت (پيمانکار) | N21: d4c438db-1288-4489-81f6-17e437ba3d19
A22: 0 | B22: آروين (پيمانکار) | C22: BDC22 | D22: 019 | E22: True | F22: False | G22: =VLOOKUP(H22,B:C,2,0) -> BDC10 | H22: تعميرات برق و ابزار دقيق | I22: =VLOOKUP(J22,Locations!B:C,2,0) -> #N/A | K22: =VLOOKUP(L22,B:C,2,0) -> BDC22 | L22: آروين (پيمانکار) | N22: 2a033f40-8506-4c71-9f6a-8c9ed231a8f9

Sheet Systems
A1: Row Status | B1: Name | C1: PSCMMSID | D1: ISProduction | E1: Org_PSCMMSID | F1: OrgName | G1: ParentSystem_PSCMMSID | H1: ParentSystemName | I1: Locations_PSCMMSID | J1: LocationsName | K1: AssetCriticality_PSCMMSID | L1: Criticality | N1: ID
A2: ({0:No Change},{1: New},{2: Update}) | B2: Systems Name | C2: Systems Id ( Sys ) | D2: IS Production? | E2: Org Id | F2: OrgName | G2: Parent Systems Id | H2: ParentSystemName | I2: Locations Id | J2: LocationsName | K2: Criticality Id | L2: Criticality | N2: ID
A3: 0 | B3: Chadormalu Industrial Company | C3: Sys1 | E3: =VLOOKUP(F3,Organization!B:C,2,0) -> #N/A | G3: =VLOOKUP(H3,B:C,2,0) -> #N/A | I3: =VLOOKUP(J3,Locations!B:C,2,0) -> #N/A | K3: =VLOOKUP(L3,AssetCriticality!B:C,2,0) -> #N/A | N3: 0fb5cde5-63db-4def-b4cd-f0224ee4b9ca
A4: 0 | B4: Pelletizing Plant | C4: Sys2 | E4: =VLOOKUP(F4,Organization!B:C,2,0) -> #N/A | G4: =VLOOKUP(H4,B:C,2,0) -> Sys1 | H4: Chadormalu Industrial Company | I4: =VLOOKUP(J4,Locations!B:C,2,0) -> #N/A | K4: =VLOOKUP(L4,AssetCriticality!B:C,2,0) -> #N/A | N4: 91794bd7-adc1-49e1-bbbf-34b6fcf65f78
A5: 0 | B5: Concentrate Receiving, Stockpiling & Reclaiming | C5: Sys3 | E5: =VLOOKUP(F5,Organization!B:C,2,0) -> #N/A | G5: =VLOOKUP(H5,B:C,2,0) -> Sys2 | H5: Pelletizing Plant | I5: =VLOOKUP(J5,Locations!B:C,2,0) -> #N/A | K5: =VLOOKUP(L5,AssetCriticality!B:C,2,0) -> #N/A | N5: 9f4df4f7-a46f-41fb-9553-fce71c7b0ac2
A6: 0 | B6: Limestone Drying & Grinding | C6: Sys4 | E6: =VLOOKUP(F6,Organization!B:C,2,0) -> #N/A | G6: =VLOOKUP(H6,B:C,2,0) -> Sys2 | H6: Pelletizing Plant | I6: =VLOOKUP(J6,Locations!B:C,2,0) -> #N/A | K6: =VLOOKUP(L6,AssetCriticality!B:C,2,0) -> #N/A | N6: 3c9a4d28-3a5c-4486-ba98-1e87cd73ec79
A7: 0 | B7: Bentonite Receiving Area | C7: Sys5 | E7: =VLOOKUP(F7,Organization!B:C,2,0) -> #N/A | G7: =VLOOKUP(H7,B:C,2,0) -> Sys2 | H7: Pelletizing Plant | I7: =VLOOKUP(J7,Locations!B:C,2,0) -> #N/A | K7: =VLOOKUP(L7,AssetCriticality!B:C,2,0) -> #N/A | N7: 6996fab7-2ca6-43dc-989a-701b11047251
A8: 0 | B8: Mixing Area | C8: Sys6 | E8: =VLOOKUP(F8,Organization!B:C,2,0) -> #N/A | G8: =VLOOKUP(H8,B:C,2,0) -> Sys2 | H8: Pelletizing Plant | I8: =VLOOKUP(J8,Locations!B:C,2,0) -> #N/A | K8: =VLOOKUP(L8,AssetCriticality!B:C,2,0) -> #N/A | N8: ac48514e-dfb9-433c-bfd7-2143bd5cbb5f
A9: 0 | B9: Balling Area | C9: Sys7 | E9: =VLOOKUP(F9,Organization!B:C,2,0) -> #N/A | G9: =VLOOKUP(H9,B:C,2,0) -> Sys2 | H9: Pelletizing Plant | I9: =VLOOKUP(J9,Locations!B:C,2,0) -> #N/A | K9: =VLOOKUP(L9,AssetCriticality!B:C,2,0) -> #N/A | N9: 6f853495-d322-4e85-9bac-a07b30b631c6
A10: 0 | B10: Induration | C10: Sys8 | E10: =VLOOKUP(F10,Organization!B:C,2,0) -> #N/A | G10: =VLOOKUP(H10,B:C,2,0) -> Sys2 | H10: Pelletizing Plant | I10: =VLOOKUP(J10,Locations!B:C,2,0) -> #N/A | K10: =VLOOKUP(L10,AssetCriticality!B:C,2,0) -> #N/A | N10: 89d673ec-c612-4d31-a1a3-19a155f6c56c
A11: 0 | B11: Product Stockpilling, Reclaiming & Load-out | C11: Sys9 | E11: =VLOOKUP(F11,Organization!B:C,2,0) -> #N/A | G11: =VLOOKUP(H11,B:C,2,0) -> Sys2 | H11: Pelletizing Plant | I11: =VLOOKUP(J11,Locations!B:C,2,0) -> #N/A | K11: =VLOOKUP(L11,AssetCriticality!B:C,2,0) -> #N/A | N11: 31a6824c-ec5c-4c2c-9a42-89b864e8afee
A12: 0 | B12: Waste Reclamation | C12: Sys10 | E12: =VLOOKUP(F12,Organization!B:C,2,0) -> #N/A | G12: =VLOOKUP(H12,B:C,2,0) -> Sys2 | H12: Pelletizing Plant | I12: =VLOOKUP(J12,Locations!B:C,2,0) -> #N/A | K12: =VLOOKUP(L12,AssetCriticality!B:C,2,0) -> #N/A | N12: 77b34f56-340f-40b2-bd16-f6cf0d58bc66
A13: 0 | B13: Crane & Hoist Area | C13: Sys11 | E13: =VLOOKUP(F13,Organization!B:C,2,0) -> #N/A | G13: =VLOOKUP(H13,B:C,2,0) -> Sys2 | H13: Pelletizing Plant | I13: =VLOOKUP(J13,Locations!B:C,2,0) -> #N/A | K13: =VLOOKUP(L13,AssetCriticality!B:C,2,0) -> #N/A | N13: 827ab08c-91b1-4fa6-a097-019095488124
A14: 0 | B14: Laboratory Equipment Area | C14: Sys12 | E14: =VLOOKUP(F14,Organization!B:C,2,0) -> #N/A | G14: =VLOOKUP(H14,B:C,2,0) -> Sys2 | H14: Pelletizing Plant | I14: =VLOOKUP(J14,Locations!B:C,2,0) -> #N/A | K14: =VLOOKUP(L14,AssetCriticality!B:C,2,0) -> #N/A | N14: fc02644b-970c-427d-a27b-b834a86ed37d
A15: 0 | B15: Machine Shop Equipment | C15: Sys13 | E15: =VLOOKUP(F15,Organization!B:C,2,0) -> #N/A | G15: =VLOOKUP(H15,B:C,2,0) -> Sys2 | H15: Pelletizing Plant | I15: =VLOOKUP(J15,Locations!B:C,2,0) -> #N/A | K15: =VLOOKUP(L15,AssetCriticality!B:C,2,0) -> #N/A | N15: 7687dc4b-cea8-421c-8974-f95345e57c8d
... A89: 0 | B89: Transport | C89: Sys87 | E89: =VLOOKUP(F89,Organization!B:C,2,0) -> #N/A | G89: =VLOOKUP(H89,B:C,2,0) -> Sys20 | H89: Ancillary Building | I89: =VLOOKUP(J89,Locations!B:C,2,0) -> #N/A | K89: =VLOOKUP(L89,AssetCriticality!B:C,2,0) -> #N/A | N89: dcba87fd-99e4-4df2-8fa1-1230c9c34477

Sheet Asset
A1: Row Status | B1: AssetNumber | C1: PSCMMSID | D1: AssetDescription | E1: SerialNo | F1: Manufacturer | G1: Model | H1: AsseClass_PSCMMSID | I1: AssetClassName | J1: AssetCategory_PSCMMSID | K1: category-class | L1: Locations_PSCMMSID | M1: ParentLocationName | N1: ParentAsset_PSCMMSID | O1: ParentAssetNumber | P1: ParentSystem_PSCMMSID | Q1: ParentSystemName | R1: Criticality_PSCMMSID | S1: CriticalityName | T1: OwnerOrgUnit_PSCMMSID | U1: OwnrOrgUnitName | V1: MasterORG_PSCMMSID | W1: MasterOrgName | X1: BDAssetHealthStatus_PSCMMSID | Y1: BDAssetHealthStatusName | Z1: Consumer | AA1: PurchasePrice | AB1: PurchaseDate | AC1: ManufactureDate | AD1: CommissionDate | AE1: SafetyNotes | AF1: Production | AG1: Safety | AH1: OutOfservice | AI1: Tools | AJ1: ViewInAssetReport | AK1: ShutdownCost | AL1: PN | AM1: CN | AN1: GetParentMeter | AO1: GetParentStatus | AP1: Nottes | AQ1: TotalCapacity | AS1: ID
A2: ({0:No Change},{1: New},{2: Update}) | B2: Asset Number | C2: Asset Id ( As ) | D2: Asset Description | E2: Serial No | F2: Manufacturer | G2: Model | H2: Asset Class Id | I2: AssetClassName | J2: Asset Category Id | K2: category-class | L2: Parent Location Id | M2: ParentLocationName | N2: Parent Asset Id | O2: ParentAssetNumber | P2: Parent Systems Id | Q2: ParentSystemName | R2: Criticality Id | S2: CriticalityName | T2: Owner Org Unit Id | U2: OwnrOrgUnitName | V2: MasterORG Id | W2: MasterOrgName | X2: BDAssetHealthStatus Id | Y2: BDAssetHealthStatusName | Z2: Consumer | AA2: PurchasePrice | AB2: PurchaseDate | AC2: ManufactureDate | AD2: CommissionDate | AE2: Safety Notes | AF2: Production | AG2: Safety | AH2: OutOfservice | AI2: Tools | AJ2: ViewInAssetReport | AK2: ShutdownCost | AL2: PN | AM2: CN | AN2: GetParentMeter | AO2: GetParentStatus | AP2: Nottes | AQ2: TotalCapacity | AS2: ID
A3: 0 | B3: SCECDG0005 | C3: As1001 | D3: DIESEL GENERATOR | H3: =VLOOKUP(I3,AssetClass!B:C,2,0) -> ASCL71 | I3: Emergency | J3: =VLOOKUP(K3,AssetCategory!B:C,2,0) -> ASCA280 | K3: Diesel Generator-Emergency | L3: =VLOOKUP(M3,Locations!B:C,2,0) -> #N/A | M3: 1400 | N3: =VLOOKUP(O3,B:C,2,0) -> #N/A | P3: =VLOOKUP(Q3,Systems!B:C,2,0) -> #N/A | R3: =VLOOKUP(S3,AssetCriticality!B:C,2,0) -> AsCr3 | S3: IMPORTANT | T3: =VLOOKUP(U3,Organization!B:C,2,0) -> BDC8 | U3: توليد | V3: =VLOOKUP(W3,Organization!B:C,2,0) -> BDC2 | W3: مجتمع صنعتي معدني چادرملو | X3: =VLOOKUP(Y3,BDAssetHealthStatus!B:C,2,0) -> #N/A | AF3: 1 | AG3: 0 | AH3: 0 | AI3: 0 | AJ3: 1 | AN3: 0 | AO3: 0 | AS3: 85b2b121-fbc2-412c-8b54-0510b8a9cca1
A4: 0 | B4: SCECDG0002 | C4: As1002 | D4: DIESEL GENERATOR | H4: =VLOOKUP(I4,AssetClass!B:C,2,0) -> ASCL71 | I4: Emergency | J4: =VLOOKUP(K4,AssetCategory!B:C,2,0) -> ASCA280 | K4: Diesel Generator-Emergency | L4: =VLOOKUP(M4,Locations!B:C,2,0) -> #N/A | M4: ER02 | N4: =VLOOKUP(O4,B:C,2,0) -> #N/A | P4: =VLOOKUP(Q4,Systems!B:C,2,0) -> #N/A | R4: =VLOOKUP(S4,AssetCriticality!B:C,2,0) -> AsCr3 | S4: IMPORTANT | T4: =VLOOKUP(U4,Organization!B:C,2,0) -> BDC8 | U4: توليد | V4: =VLOOKUP(W4,Organization!B:C,2,0) -> BDC2 | W4: مجتمع صنعتي معدني چادرملو | X4: =VLOOKUP(Y4,BDAssetHealthStatus!B:C,2,0) -> #N/A | AF4: 1 | AG4: 0 | AH4: 0 | AI4: 0 | AJ4: 1 | AN4: 0 | AO4: 0 | AS4: 67e7a2ab-4922-41e4-af3a-60cc4452b583
A5: 0 | B5: SCECDG0004 | C5: As1003 | D5: DIESEL GENERATOR | H5: =VLOOKUP(I5,AssetClass!B:C,2,0) -> ASCL71 | I5: Emergency | J5: =VLOOKUP(K5,AssetCategory!B:C,2,0) -> ASCA280 | K5: Diesel Generator-Emergency | L5: =VLOOKUP(M5,Locations!B:C,2,0) -> #N/A | M5: ER02 | N5: =VLOOKUP(O5,B:C,2,0) -> #N/A | P5: =VLOOKUP(Q5,Systems!B:C,2,0) -> #N/A | R5: =VLOOKUP(S5,AssetCriticality!B:C,2,0) -> AsCr3 | S5: IMPORTANT | T5: =VLOOKUP(U5,Organization!B:C,2,0) -> BDC8 | U5: توليد | V5: =VLOOKUP(W5,Organization!B:C,2,0) -> BDC2 | W5: مجتمع صنعتي معدني چادرملو | X5: =VLOOKUP(Y5,BDAssetHealthStatus!B:C,2,0) -> #N/A | AF5: 1 | AG5: 0 | AH5: 0 | AI5: 0 | AJ5: 1 | AN5: 0 | AO5: 0 | AS5: 3b1576a3-45d5-400c-b66d-626045e0c223
A6: 0 | B6: SCECDG0003 | C6: As1004 | D6: DIESEL GENERATOR | H6: =VLOOKUP(I6,AssetClass!B:C,2,0) -> ASCL71 | I6: Emergency | J6: =VLOOKUP(K6,AssetCategory!B:C,2,0) -> ASCA280 | K6: Diesel Generator-Emergency | L6: =VLOOKUP(M6,Locations!B:C,2,0) -> #N/A | M6: ER02 | N6: =VLOOKUP(O6,B:C,2,0) -> #N/A | P6: =VLOOKUP(Q6,Systems!B:C,2,0) -> #N/A | R6: =VLOOKUP(S6,AssetCriticality!B:C,2,0) -> AsCr3 | S6: IMPORTANT | T6: =VLOOKUP(U6,Organization!B:C,2,0) -> BDC8 | U6: توليد | V6: =VLOOKUP(W6,Organization!B:C,2,0) -> BDC2 | W6: مجتمع صنعتي معدني چادرملو | X6: =VLOOKUP(Y6,BDAssetHealthStatus!B:C,2,0) -> #N/A | AF6: 1 | AG6: 0 | AH6: 0 | AI6: 0 | AJ6: 1 | AN6: 0 | AO6: 0 | AS6: e9a3e524-6f82-4979-a88b-82ca8e463071
A7: 0 | B7: SCECDG0001 | C7: As1005 | D7: DIESEL GENERATOR | H7: =VLOOKUP(I7,AssetClass!B:C,2,0) -> ASCL71 | I7: Emergency | J7: =VLOOKUP(K7,AssetCategory!B:C,2,0) -> ASCA280 | K7: Diesel Generator-Emergency | L7: =VLOOKUP(M7,Locations!B:C,2,0) -> #N/A | M7: ER02 | N7: =VLOOKUP(O7,B:C,2,0) -> #N/A | P7: =VLOOKUP(Q7,Systems!B:C,2,0) -> #N/A | R7: =VLOOKUP(S7,AssetCriticality!B:C,2,0) -> AsCr3 | S7: IMPORTANT | T7: =VLOOKUP(U7,Organization!B:C,2,0) -> BDC8 | U7: توليد | V7: =VLOOKUP(W7,Organization!B:C,2,0) -> BDC2 | W7: مجتمع صنعتي معدني چادرملو | X7: =VLOOKUP(Y7,BDAssetHealthStatus!B:C,2,0) -> #N/A | AF7: 1 | AG7: 0 | AH7: 0 | AI7: 0 | AJ7: 1 | AN7: 0 | AO7: 0 | AS7: beaaaf54-1b3f-4972-913e-dc6ac1587c0b
A8: 0 | B8: MESCRF0001 | C8: As1 | D8: رولر فيدر | H8: =VLOOKUP(I8,AssetClass!B:C,2,0) -> ASCL17 | I8: Screens | J8: =VLOOKUP(K8,AssetCategory!B:C,2,0) -> ASCA52 | K8: Roller Feeder-Screens | L8: =VLOOKUP(M8,Locations!B:C,2,0) -> #N/A | M8: 0600 | N8: =VLOOKUP(O8,B:C,2,0) -> #N/A | P8: =VLOOKUP(Q8,Systems!B:C,2,0) -> #N/A | R8: =VLOOKUP(S8,AssetCriticality!B:C,2,0) -> AsCr1 | S8: VITAL | T8: =VLOOKUP(U8,Organization!B:C,2,0) -> BDC8 | U8: توليد | V8: =VLOOKUP(W8,Organization!B:C,2,0) -> #N/A | X8: =VLOOKUP(Y8,BDAssetHealthStatus!B:C,2,0) -> #N/A | AS8: 8c18eb9e-ac5c-4fb3-8c49-6b69550208c0
A9: 0 | B9: MERSRB0001 | C9: As2 | D9: نوار نقاله رفت برگشتي | H9: =VLOOKUP(I9,AssetClass!B:C,2,0) -> ASCL15 | I9: Receiving and Stocking | J9: =VLOOKUP(K9,AssetCategory!B:C,2,0) -> ASCA43 | K9: Reciprocating Conveyor-Receiving and Stocking | L9: =VLOOKUP(M9,Locations!B:C,2,0) -> #N/A | M9: 0600 | N9: =VLOOKUP(O9,B:C,2,0) -> #N/A | P9: =VLOOKUP(Q9,Systems!B:C,2,0) -> #N/A | R9: =VLOOKUP(S9,AssetCriticality!B:C,2,0) -> AsCr1 | S9: VITAL | T9: =VLOOKUP(U9,Organization!B:C,2,0) -> BDC8 | U9: توليد | V9: =VLOOKUP(W9,Organization!B:C,2,0) -> #N/A | X9: =VLOOKUP(Y9,BDAssetHealthStatus!B:C,2,0) -> #N/A | AS9: 070623ac-4863-4c31-beee-8bbed43221f9
A10: 0 | B10: MEGBPE0001 | C10: As3 | D10: بالينگ ديسک | H10: =VLOOKUP(I10,AssetClass!B:C,2,0) -> ASCL28 | I10: Green Ball | J10: =VLOOKUP(K10,AssetCategory!B:C,2,0) -> ASCA92 | K10: Balling Disk-Green Ball | L10: =VLOOKUP(M10,Locations!B:C,2,0) -> #N/A | M10: 0600 | N10: =VLOOKUP(O10,B:C,2,0) -> #N/A | P10: =VLOOKUP(Q10,Systems!B:C,2,0) -> #N/A | R10: =VLOOKUP(S10,AssetCriticality!B:C,2,0) -> AsCr1 | S10: VITAL | T10: =VLOOKUP(U10,Organization!B:C,2,0) -> BDC8 | U10: توليد | V10: =VLOOKUP(W10,Organization!B:C,2,0) -> #N/A | X10: =VLOOKUP(Y10,BDAssetHealthStatus!B:C,2,0) -> #N/A | AS10: ee384cae-1fba-433c-9d0d-b09e3b7e48f9
A11: 0 | B11: MEGBPE0002 | C11: As4 | D11: بالينگ ديسک | H11: =VLOOKUP(I11,AssetClass!B:C,2,0) -> ASCL28 | I11: Green Ball | J11: =VLOOKUP(K11,AssetCategory!B:C,2,0) -> ASCA92 | K11: Balling Disk-Green Ball | L11: =VLOOKUP(M11,Locations!B:C,2,0) -> #N/A | M11: 0600 | N11: =VLOOKUP(O11,B:C,2,0) -> #N/A | P11: =VLOOKUP(Q11,Systems!B:C,2,0) -> #N/A | R11: =VLOOKUP(S11,AssetCriticality!B:C,2,0) -> AsCr1 | S11: VITAL | T11: =VLOOKUP(U11,Organization!B:C,2,0) -> BDC8 | U11: توليد | V11: =VLOOKUP(W11,Organization!B:C,2,0) -> #N/A | X11: =VLOOKUP(Y11,BDAssetHealthStatus!B:C,2,0) -> #N/A | AS11: 9ac0925d-38d3-4204-baa0-55c0ea5cfd6e
A12: 0 | B12: MEGBPE0003 | C12: As5 | D12: بالينگ ديسک | H12: =VLOOKUP(I12,AssetClass!B:C,2,0) -> ASCL28 | I12: Green Ball | J12: =VLOOKUP(K12,AssetCategory!B:C,2,0) -> ASCA92 | K12: Balling Disk-Green Ball | L12: =VLOOKUP(M12,Locations!B:C,2,0) -> #N/A | M12: 0600 | N12: =VLOOKUP(O12,B:C,2,0) -> #N/A | P12: =VLOOKUP(Q12,Systems!B:C,2,0) -> #N/A | R12: =VLOOKUP(S12,AssetCriticality!B:C,2,0) -> AsCr1 | S12: VITAL | T12: =VLOOKUP(U12,Organization!B:C,2,0) -> BDC8 | U12: توليد | V12: =VLOOKUP(W12,Organization!B:C,2,0) -> #N/A | X12: =VLOOKUP(Y12,BDAssetHealthStatus!B:C,2,0) -> #N/A | AS12: 754331b1-2688-41c2-b941-f661223c7ee6
A13: 0 | B13: MEGBPE0004 | C13: As6 | D13: بالينگ ديسک | H13: =VLOOKUP(I13,AssetClass!B:C,2,0) -> ASCL28 | I13: Green Ball | J13: =VLOOKUP(K13,AssetCategory!B:C,2,0) -> ASCA92 | K13: Balling Disk-Green Ball | L13: =VLOOKUP(M13,Locations!B:C,2,0) -> #N/A | M13: 0600 | N13: =VLOOKUP(O13,B:C,2,0) -> #N/A | P13: =VLOOKUP(Q13,Systems!B:C,2,0) -> #N/A | R13: =VLOOKUP(S13,AssetCriticality!B:C,2,0) -> AsCr1 | S13: VITAL | T13: =VLOOKUP(U13,Organization!B:C,2,0) -> BDC8 | U13: توليد | V13: =VLOOKUP(W13,Organization!B:C,2,0) -> #N/A | X13: =VLOOKUP(Y13,BDAssetHealthStatus!B:C,2,0) -> #N/A | AS13: 479b9f93-d719-40cd-bc19-9f2968a909e0
A14: 0 | B14: MEGBPE0005 | C14: As7 | D14: بالينگ ديسک | H14: =VLOOKUP(I14,AssetClass!B:C,2,0) -> ASCL28 | I14: Green Ball | J14: =VLOOKUP(K14,AssetCategory!B:C,2,0) -> ASCA92 | K14: Balling Disk-Green Ball | L14: =VLOOKUP(M14,Locations!B:C,2,0) -> #N/A | M14: 0600 | N14: =VLOOKUP(O14,B:C,2,0) -> #N/A | P14: =VLOOKUP(Q14,Systems!B:C,2,0) -> #N/A | R14: =VLOOKUP(S14,AssetCriticality!B:C,2,0) -> AsCr1 | S14: VITAL | T14: =VLOOKUP(U14,Organization!B:C,2,0) -> BDC8 | U14: توليد | V14: =VLOOKUP(W14,Organization!B:C,2,0) -> #N/A | X14: =VLOOKUP(Y14,BDAssetHealthStatus!B:C,2,0) -> #N/A | AS14: 3d5094a6-1883-4105-a0d0-6d3d88037f9b
A15: 0 | B15: MEGBPE0006 | C15: As8 | D15: بالينگ ديسک | H15: =VLOOKUP(I15,AssetClass!B:C,2,0) -> ASCL28 | I15: Green Ball | J15: =VLOOKUP(K15,AssetCategory!B:C,2,0) -> ASCA92 | K15: Balling Disk-Green Ball | L15: =VLOOKUP(M15,Locations!B:C,2,0) -> #N/A | M15: 0600 | N15: =VLOOKUP(O15,B:C,2,0) -> #N/A | P15: =VLOOKUP(Q15,Systems!B:C,2,0) -> #N/A | R15: =VLOOKUP(S15,AssetCriticality!B:C,2,0) -> AsCr1 | S15: VITAL | T15: =VLOOKUP(U15,Organization!B:C,2,0) -> BDC8 | U15: توليد | V15: =VLOOKUP(W15,Organization!B:C,2,0) -> #N/A | X15: =VLOOKUP(Y15,BDAssetHealthStatus!B:C,2,0) -> #N/A | AS15: 0dfaba73-c676-4a6a-b460-36e29291d6cd
A16: 0 | B16: MESCRS0001 | C16: As9 | D16: رولر کلاسيفاير | H16: =VLOOKUP(I16,AssetClass!B:C,2,0) -> ASCL17 | I16: Screens | J16: =VLOOKUP(K16,AssetCategory!B:C,2,0) -> ASCA53 | K16: Roller Classifier-Screens | L16: =VLOOKUP(M16,Locations!B:C,2,0) -> #N/A | M16: 0600 | N16: =VLOOKUP(O16,B:C,2,0) -> #N/A | P16: =VLOOKUP(Q16,Systems!B:C,2,0) -> #N/A | R16: =VLOOKUP(S16,AssetCriticality!B:C,2,0) -> AsCr1 | S16: VITAL | T16: =VLOOKUP(U16,Organization!B:C,2,0) -> BDC8 | U16: توليد | V16: =VLOOKUP(W16,Organization!B:C,2,0) -> #N/A | X16: =VLOOKUP(Y16,BDAssetHealthStatus!B:C,2,0) -> #N/A | AS16: ea10668a-b17f-426b-bd0a-1fb2105f0019
A17: 0 | B17: MESCRS0002 | C17: As10 | D17: رولر کلاسيفاير | H17: =VLOOKUP(I17,AssetClass!B:C,2,0) -> ASCL17 | I17: Screens | J17: =VLOOKUP(K17,AssetCategory!B:C,2,0) -> ASCA53 | K17: Roller Classifier-Screens | L17: =VLOOKUP(M17,Locations!B:C,2,0) -> #N/A | M17: 0600 | N17: =VLOOKUP(O17,B:C,2,0) -> #N/A | P17: =VLOOKUP(Q17,Systems!B:C,2,0) -> #N/A | R17: =VLOOKUP(S17,AssetCriticality!B:C,2,0) -> AsCr1 | S17: VITAL | T17: =VLOOKUP(U17,Organization!B:C,2,0) -> BDC8 | U17: توليد | V17: =VLOOKUP(W17,Organization!B:C,2,0) -> #N/A | X17: =VLOOKUP(Y17,BDAssetHealthStatus!B:C,2,0) -> #N/A | AS17: 0907bcdd-19e1-40b0-94d6-d82889053d08
A18: 0 | B18: MESCRS0003 | C18: As11 | D18: رولر کلاسيفاير | H18: =VLOOKUP(I18,AssetClass!B:C,2,0) -> ASCL17 | I18: Screens | J18: =VLOOKUP(K18,AssetCategory!B:C,2,0) -> ASCA53 | K18: Roller Classifier-Screens | L18: =VLOOKUP(M18,Locations!B:C,2,0) -> #N/A | M18: 0600 | N18: =VLOOKUP(O18,B:C,2,0) -> #N/A | P18: =VLOOKUP(Q18,Systems!B:C,2,0) -> #N/A | R18: =VLOOKUP(S18,AssetCriticality!B:C,2,0) -> AsCr1 | S18: VITAL | T18: =VLOOKUP(U18,Organization!B:C,2,0) -> BDC8 | U18: توليد | V18: =VLOOKUP(W18,Organization!B:C,2,0) -> #N/A | X18: =VLOOKUP(Y18,BDAssetHealthStatus!B:C,2,0) -> #N/A | AS18: f1017337-6378-46c1-8561-4045ee23baab
A19: 0 | B19: MESCRS0004 | C19: As12 | D19: رولر کلاسيفاير | H19: =VLOOKUP(I19,AssetClass!B:C,2,0) -> ASCL17 | I19: Screens | J19: =VLOOKUP(K19,AssetCategory!B:C,2,0) -> ASCA53 | K19: Roller Classifier-Screens | L19: =VLOOKUP(M19,Locations!B:C,2,0) -> #N/A | M19: 0600 | N19: =VLOOKUP(O19,B:C,2,0) -> #N/A | P19: =VLOOKUP(Q19,Systems!B:C,2,0) -> #N/A | R19: =VLOOKUP(S19,AssetCriticality!B:C,2,0) -> AsCr1 | S19: VITAL | T19: =VLOOKUP(U19,Organization!B:C,2,0) -> BDC8 | U19: توليد | V19: =VLOOKUP(W19,Organization!B:C,2,0) -> #N/A | X19: =VLOOKUP(Y19,BDAssetHealthStatus!B:C,2,0) -> #N/A | AS19: f429543b-8cce-481e-a8df-ad5940753782
... A1002: 0 | B1002: ELUPUS0013 | C1002: As1000 | D1002: UPS | H1002: =VLOOKUP(I1002,AssetClass!B:C,2,0) -> ASCL41 | I1002: Uninterruptible Power Supply | J1002: =VLOOKUP(K1002,AssetCategory!B:C,2,0) -> ASCA134 | K1002: Single Ups With Bypass-Uninterruptible Power Supply | L1002: =VLOOKUP(M1002,Locations!B:C,2,0) -> #N/A | M1002: ER | N1002: =VLOOKUP(O1002,B:C,2,0) -> #N/A | P1002: =VLOOKUP(Q1002,Systems!B:C,2,0) -> #N/A | R1002: =VLOOKUP(S1002,AssetCriticality!B:C,2,0) -> AsCr5 | S1002: ESSENTIAL | T1002: =VLOOKUP(U1002,Organization!B:C,2,0) -> BDC8 | U1002: توليد | V1002: =VLOOKUP(W1002,Organization!B:C,2,0) -> #N/A | X1002: =VLOOKUP(Y1002,BDAssetHealthStatus!B:C,2,0) -> #N/A | AS1002: 71578cb7-f0e7-436d-9086-f92db3089935
