Workbook

Sheet تجهیزات صنعتی گندله سازی
A1: گروه اولویت | B1: Points range | C1: تعداد تجهیزات | D1: درصد پیشرفت تکسونامی تجهیزات | F1: ناحیه | G1: 100 | H1: 200 | I1: 300 | J1: 500 | K1: 600 | L1: 700 | M1: 800 | N1: 900 | O1: 1000 | P1: 1100 | Q1: 1200 | R1: 1300 | S1: 1400 | T1: ER | U1: 1500 | V1: تعداد کل | AA1: وزن درصدی هر ستون
A2: VITAL | B2: 5.29> | C2: 117 | D2: =AVERAGEIF($B$8:$B$595,"vital",$M$8:$M$595) -> 0.89059829 | F2: تعداد تجهیزات | G2: =COUNTIF($A$8:$A$1048576,G1) -> 67 | H2: =COUNTIF($A$8:$A$1048576,H1) -> 18 | I2: =COUNTIF($A$8:$A$1048576,I1) -> 15 | J2: =COUNTIF($A$8:$A$1048576,J1) -> 43 | K2: =COUNTIF($A$8:$A$1048576,K1) -> 49 | L2: =COUNTIF($A$8:$A$1048576,L1) -> 74 | M2: =COUNTIF($A$8:$A$1048576,M1) -> 119 | N2: =COUNTIF($A$8:$A$1048576,N1) -> 102 | ... U2: =COUNTIF($A$8:$A$1048576,U1) -> 0 | V2: =SUM(G2:U2) -> 588 | AA2: 0.15 | AB2: 0.45 | AC2: 0.28 | AD2: 0.02 | AE2: 0.1 | AF2: =SUM(AA2:AE2) -> 1
A3: ESSENTIAL | B3: (3.98-5.29) | C3: 188 | D3: =AVERAGEIF($B$8:$B$595,"ESSENTIAL",$M$8:$M$595) -> 0.54074468 | F3: وزن تجهیز | G3: 6.5 | H3: 3 | I3: 3.5 | J3: 12 | K3: 18 | L3: 24 | M3: 8 | N3: 9 | O3: 2.5 | P3: 1 | Q3: 0.5 | R3: 5 | S3: 0.5 | T3: 6 | U3: 0.5 | V3: =SUM(G3:U3) -> 100
A4: IMPORTANT | B4: (2.67-3.98) | C4: 123 | D4: =AVERAGEIF($B$8:$B$595,"IMPORTANT",$M$8:$M$595) -> 0.39673171 | F4: درصد پیشرفت ناحیه | G4: =SUMIF($A$8:$A$1048576,"100",$M$8:$M$1048576)/G2 -> 0.85504478 | H4: =SUMIF($A$8:$A$1048576,"200",$M$8:$M$1048576)/H2 -> 0.25722222 | I4: =SUMIF($A$8:$A$1048576,"300",$M$8:$M$1048576)/I2 -> 0.34 | J4: =SUMIF($A$8:$A$1048576,"500",$M$8:$M$1048576)/J2 -> 0.59767442 | K4: =SUMIF($A$8:$A$1048576,"600",$M$8:$M$1048576)/K2 -> 0.90979592 | L4: =SUMIF($A$8:$A$1048576,"700",$M$8:$M$1048576)/L2 -> 0.94405405 | M4: =SUMIF($A$8:$A$1048576,"800",$M$8:$M$1048576)/M2 -> 0.073445378 | N4: =SUMIF($A$8:$A$1048576,"900",$M$8:$M$1048576)/N2 -> 0.55254902 | O4: =SUMIF($A$8:$A$1048576,"1000",$M$8:$M$1048576)/O2 -> 0 | P4: =SUMIF($A$8:$A$1048576,"1100",$M$8:$M$1048576)/P2 -> 0 | Q4: =SUMIF($A$8:$A$1048576,"1200",$M$8:$M$1048576)/Q2 -> #DIV/0! | R4: =SUMIF($A$8:$A$1048576,"1300",$M$8:$M$1048576)/R2 -> 0.18138889 | S4: =SUMIF($A$8:$A$1048576,"1400",$M$8:$M$1048576)/S2 -> 0 | T4: =SUMIF($A$8:$A$1048576,"ER",$M$8:$M$1048576)/T2 -> #DIV/0! | U4: =SUMIF($A$8:$A$1048576,"1500",$M$8:$M$1048576)/U2 -> #DIV/0! | V4: درصد کل
A5: NORMAL | B5: <2.67 | C5: 159 | D5: =AVERAGEIF($B$8:$B$595,"NORMAL",$M$8:$M$595) -> 0.19283019 | G5: =(G2+G3)*G4/($V$2+$V$3) -> 0.091345627 | H5: =(H2+H3)*H4/($V$2+$V$3) -> 0.0078512597 | I5: =(I2+I3)*I4/($V$2+$V$3) -> 0.0091424419 | J5: =(J2+J3)*J4/($V$2+$V$3) -> 0.047779205 | K5: =(K2+K3)*K4/($V$2+$V$3) -> 0.088599312 | L5: =(L2+L3)*L4/($V$2+$V$3) -> 0.13447282 | M5: =(M2+M3)*M4/($V$2+$V$3) -> 0.013557504 | N5: =(N2+N3)*N4/($V$2+$V$3) -> 0.089146717 | ... P5: =(P2+P3)*P4/($V$2+$V$3) -> 0 | R5: =(R2+R3)*R4/($V$2+$V$3) -> 0.020300791 | S5: =(S2+S3)*S4/($V$2+$V$3) -> 0 | V5: =SUBTOTAL(9,G5:U5) -> 0.50219567
A7: ناحیه | B7: اولویت | C7: Asset Tag No | D7: نام تجهیز | E7: کارشناس انجام دهنده مکانیک و تاسیسات | F7: کارشناس انجام دهنده هیدرولیک و روانکاری | G7: کارشناس انجام دهنده برق | H7: برگزاری جلسه مشترک و تهیه درخت روی وایت برد | I7: پیشرفت فایل اکسل مکانیک | J7: پیشرفت فایل اکسل برق | K7: کنترل فایل توسط CPG | L7: جمع بندی فایل اکسل نهایی | M7: درصد تکمیل فایل نهایی
A8: 100 | B8: =VLOOKUP(C8,Sheet1!$A$2:$B$1132,2,FALSE) -> VITAL | C8: 0110AP01 | D8: اپرون فیدر | E8: مهدی زاده | F8: زارعی | G8: غفاری | H8: 1 | I8: 1 | J8: 1 | K8: 1 | L8: 1 | M8: =SUMPRODUCT(H8:L8,$AA$2:$AE$2) -> 1
A9: 100 | B9: =VLOOKUP(C9,Sheet1!$A$2:$B$1132,2,FALSE) -> VITAL | C9: 0110BC01 | D9: نوار نقاله | E9: مهدی زاده | F9: زارعی | G9: غفاری | H9: 1 | I9: 1 | J9: 1 | K9: 1 | L9: 1 | M9: =SUMPRODUCT(H9:L9,$AA$2:$AE$2) -> 1
A10: 100 | B10: =VLOOKUP(C10,Sheet1!$A$2:$B$1132,2,FALSE) -> VITAL | C10: 0110BC02 | D10: نوار نقاله | E10: مهدی زاده | F10: زارعی | G10: غفاری | H10: 1 | I10: 1 | J10: 1 | K10: 1 | L10: 1 | M10: =SUMPRODUCT(H10:L10,$AA$2:$AE$2) -> 1
A11: 100 | B11: =VLOOKUP(C11,Sheet1!$A$2:$B$1132,2,FALSE) -> VITAL | C11: 0110BF01 | D11: بگ فیلتر | E11: مهدی زاده | F11: زارعی | G11: غفاری | H11: 1 | I11: 1 | J11: 1 | K11: 1 | L11: 1 | M11: =SUMPRODUCT(H11:L11,$AA$2:$AE$2) -> 1
A12: 100 | B12: =VLOOKUP(C12,Sheet1!$A$2:$B$1132,2,FALSE) -> NORMAL | C12: 0110BW01 | D12: بلت اسکیل | E12: مهدی زاده | F12: زارعی | G12: غفاری | H12: 1 | I12: 1 | J12: 1 | K12: 1 | L12: 1 | M12: =SUMPRODUCT(H12:L12,$AA$2:$AE$2) -> 1
A13: 100 | B13: =VLOOKUP(C13,Sheet1!$A$2:$B$1132,2,FALSE) -> ESSENTIAL | C13: 0110CP01 | D13: کمپرسور هوای واگن دامپر | E13: عزیزی | F13: زارعی | G13: غفاری | H13: 1 | I13: 1 | J13: 1 | K13: 1 | L13: 1 | M13: =SUMPRODUCT(H13:L13,$AA$2:$AE$2) -> 1
A14: 100 | B14: =VLOOKUP(C14,Sheet1!$A$2:$B$1132,2,FALSE) -> ESSENTIAL | C14: 0110CP02 | D14: کمپرسور هوای واگن دامپر | E14: عزیزی | F14: زارعی | G14: غفاری | H14: 1 | I14: 1 | J14: 1 | K14: 1 | L14: 1 | M14: =SUMPRODUCT(H14:L14,$AA$2:$AE$2) -> 1
A15: 100 | B15: =VLOOKUP(C15,Sheet1!$A$2:$B$1132,2,FALSE) -> IMPORTANT | C15: 0110FE01 | D15: روتاری فیدر بگ فیلتر | E15: مهدی زاده | F15: زارعی | G15: غفاری | H15: 1 | I15: 1 | J15: 1 | K15: 1 | L15: 1 | M15: =SUMPRODUCT(H15:L15,$AA$2:$AE$2) -> 1
A16: 100 | B16: =VLOOKUP(C16,Sheet1!$A$2:$B$1132,2,FALSE) -> IMPORTANT | C16: 0110FN01 | D16: فن منگان گریسی | E16: توانا/کارگر | F16: زارعی | G16: غفاری | H16: 1 | I16: 1 | J16: 1 | K16: 1 | L16: 1 | M16: =SUMPRODUCT(H16:L16,$AA$2:$AE$2) -> 1
A17: 100 | B17: =VLOOKUP(C17,Sheet1!$A$2:$B$1132,2,FALSE) -> IMPORTANT | C17: 0110GA01 | D17: گیت | E17: مهدی زاده | F17: زارعی | G17: غفاری | H17: 1 | I17: 1 | J17: 1 | K17: 1 | L17: 1 | M17: =SUMPRODUCT(H17:L17,$AA$2:$AE$2) -> 1
A18: 100 | B18: =VLOOKUP(C18,Sheet1!$A$2:$B$1132,2,FALSE) -> IMPORTANT | C18: 0110HP01 | D18: هاپر | E18: مهدی زاده | F18: زارعی | G18: غفاری | H18: 1 | I18: 1 | J18: 1 | K18: 1 | L18: 1 | M18: =SUMPRODUCT(H18:L18,$AA$2:$AE$2) -> 1
A19: 100 | B19: =VLOOKUP(C19,Sheet1!$A$2:$B$1132,2,FALSE) -> IMPORTANT | C19: 0110MD01 | D19: متال دتکتور | E19: مهدی زاده | F19: زارعی | G19: غفاری | H19: 1 | I19: 1 | J19: 1 | K19: 1 | L19: 1 | M19: =SUMPRODUCT(H19:L19,$AA$2:$AE$2) -> 1
... A35: 100 | B35: =VLOOKUP(C35,Sheet1!$A$2:$B$1132,2,FALSE) -> IMPORTANT | C35: 0120GA01 | D35: گیت | E35: مهدی زاده | F35: زارعی | G35: غفاری | H35: 1 | I35: 1 | J35: 1 | K35: 1 | L35: 1 | M35: =SUMPRODUCT(H35:L35,$AA$2:$AE$2) -> 1
A36: 100 | B36: =VLOOKUP(C36,Sheet1!$A$2:$B$1132,2,FALSE) -> IMPORTANT | C36: 0120MD01 | D36: متال دتکتور | E36: مهدی زاده | F36: زارعی | G36: غفاری | H36: 1 | J36: 1 | M36: =SUMPRODUCT(H36:L36,$AA$2:$AE$2) -> 0.43
A37: 100 | B37: =VLOOKUP(C37,Sheet1!$A$2:$B$1132,2,FALSE) -> VITAL | C37: 0120RR01 | D37: ماشین برداشت | E37: مهدی زاده | F37: زارعی | G37: غفاری | H37: 1 | I37: 1 | J37: 0.5 | M37: =SUMPRODUCT(H37:L37,$AA$2:$AE$2) -> 0.74
A38: 100 | B38: =VLOOKUP(C38,Sheet1!$A$2:$B$1132,2,FALSE) -> IMPORTANT | C38: 0120SM01 | D38: نمونه گیر | E38: مهدی زاده | F38: زارعی | G38: غفاری | H38: 1 | I38: 1 | J38: 1 | K38: 1 | L38: 1 | M38: =SUMPRODUCT(H38:L38,$AA$2:$AE$2) -> 1
A39: 100 | B39: =VLOOKUP(C39,Sheet1!$A$2:$B$1132,2,FALSE) -> NORMAL | C39: 0120TT01 | D39: ترانسفر تاور | E39: مهدی زاده | F39: زارعی | G39: غفاری | H39: 1 | I39: 1 | J39: 1 | K39: 1 | L39: 1 | M39: =SUMPRODUCT(H39:L39,$AA$2:$AE$2) -> 1
A40: 100 | B40: =VLOOKUP(C40,Sheet1!$A$2:$B$1132,2,FALSE) -> NORMAL | C40: 0120TT02 | D40: ترانسفر تاور | E40: مهدی زاده | F40: زارعی | G40: غفاری | H40: 1 | I40: 1 | J40: 1 | K40: 1 | L40: 1 | M40: =SUMPRODUCT(H40:L40,$AA$2:$AE$2) -> 1
A41: 100 | B41: =VLOOKUP(C41,Sheet1!$A$2:$B$1132,2,FALSE) -> ESSENTIAL | C41: 0130BC01 | D41: نوار نقاله | E41: مهدی زاده | F41: زارعی | G41: غفاری | H41: 1 | I41: 1 | J41: 1 | K41: 1 | L41: 1 | M41: =SUMPRODUCT(H41:L41,$AA$2:$AE$2) -> 1
A42: 100 | B42: =VLOOKUP(C42,Sheet1!$A$2:$B$1132,2,FALSE) -> NORMAL | C42: 0130BW01 | D42: بلت اسکیل | E42: مهدی زاده | F42: زارعی | G42: غفاری | H42: 1 | I42: 1 | J42: 1 | K42: 1 | L42: 1 | M42: =SUMPRODUCT(H42:L42,$AA$2:$AE$2) -> 1
A43: 100 | B43: =VLOOKUP(C43,Sheet1!$A$2:$B$1132,2,FALSE) -> IMPORTANT | C43: 0130CH01 | D43: داکت | E43: مهدی زاده | F43: زارعی | G43: غفاری | H43: 1 | J43: 1 | M43: =SUMPRODUCT(H43:L43,$AA$2:$AE$2) -> 0.43
A44: 100 | B44: =VLOOKUP(C44,Sheet1!$A$2:$B$1132,2,FALSE) -> IMPORTANT | C44: 0130HP01 | D44: هاپر | E44: مهدی زاده | F44: زارعی | G44: غفاری | H44: 1 | I44: 1 | M44: =SUMPRODUCT(H44:L44,$AA$2:$AE$2) -> 0.6
A45: 100 | B45: =VLOOKUP(C45,Sheet1!$A$2:$B$1132,2,FALSE) -> IMPORTANT | C45: 0130MD01 | D45: متال دتکتور | E45: مهدی زاده | F45: زارعی | G45: غفاری | H45: 1 | J45: 1 | M45: =SUMPRODUCT(H45:L45,$AA$2:$AE$2) -> 0.43
A46: 100 | B46: =VLOOKUP(C46,Sheet1!$A$2:$B$1132,2,FALSE) -> IMPORTANT | C46: 0130MS01 | D46: مگنتیک سپریتور | E46: مهدی زاده | F46: زارعی | G46: غفاری | H46: 1 | J46: 0.3 | M46: =SUMPRODUCT(H46:L46,$AA$2:$AE$2) -> 0.234
A47: 100 | B47: =VLOOKUP(C47,Sheet1!$A$2:$B$1132,2,FALSE) -> IMPORTANT | C47: 0130TS01 | D47: باسکول | E47: مهدی زاده | F47: زارعی | G47: غفاری | H47: 1 | J47: 0.3 | M47: =SUMPRODUCT(H47:L47,$AA$2:$AE$2) -> 0.234
A48: 100 | B48: =VLOOKUP(C48,Sheet1!$A$2:$B$1132,2,FALSE) -> VITAL | C48: 0150BC01 | D48: نوار نقاله | E48: مهدی زاده | F48: زارعی | G48: غفاری | H48: 1 | I48: 1 | J48: 1 | K48: 1 | L48: 1 | M48: =SUMPRODUCT(H48:L48,$AA$2:$AE$2) -> 1
A49: 100 | B49: =VLOOKUP(C49,Sheet1!$A$2:$B$1132,2,FALSE) -> VITAL | C49: 0150BC02 | D49: نوار نقاله | E49: مهدی زاده | F49: زارعی | G49: غفاری | H49: 1 | I49: 1 | J49: 1 | K49: 1 | L49: 1 | M49: =SUMPRODUCT(H49:L49,$AA$2:$AE$2) -> 1
A50: 100 | B50: =VLOOKUP(C50,Sheet1!$A$2:$B$1132,2,FALSE) -> VITAL | C50: 0150BC03 | D50: نوار نقاله | E50: مهدی زاده | F50: زارعی | G50: غفاری | H50: 1 | I50: 1 | J50: 1 | K50: 1 | L50: 1 | M50: =SUMPRODUCT(H50:L50,$AA$2:$AE$2) -> 1
A51: 100 | B51: =VLOOKUP(C51,Sheet1!$A$2:$B$1132,2,FALSE) -> IMPORTANT | C51: 0150BI01 | D51: بین | E51: مهدی زاده | F51: زارعی | G51: غفاری | H51: 1 | I51: 1 | J51: 1 | K51: 1 | L51: 1 | M51: =SUMPRODUCT(H51:L51,$AA$2:$AE$2) -> 1
A52: 100 | B52: =VLOOKUP(C52,Sheet1!$A$2:$B$1132,2,FALSE) -> ESSENTIAL | C52: 0150CP01 | D52: کمپرسور هوای HPGR | E52: عزیزی | F52: زارعی | G52: غفاری | H52: 1 | J52: 1 | M52: =SUMPRODUCT(H52:L52,$AA$2:$AE$2) -> 0.43
A53: 100 | B53: =VLOOKUP(C53,Sheet1!$A$2:$B$1132,2,FALSE) -> VITAL | C53: 0150EC01 | D53: کولینگ تاور | E53: عزیزی | F53: زارعی | G53: غفاری | H53: 1 | I53: 1 | J53: 1 | K53: 1 | L53: 1 | M53: =SUMPRODUCT(H53:L53,$AA$2:$AE$2) -> 1
A54: 100 | B54: =VLOOKUP(C54,Sheet1!$A$2:$B$1132,2,FALSE) -> IMPORTANT | C54: 0150GA01 | D54: گیت | E54: مهدی زاده | F54: زارعی | G54: غفاری | H54: 1 | J54: 1 | M54: =SUMPRODUCT(H54:L54,$AA$2:$AE$2) -> 0.43
A55: 100 | B55: =VLOOKUP(C55,Sheet1!$A$2:$B$1132,2,FALSE) -> NORMAL | C55: 0150PI01 | D55: پایپینگ | E55: عزیزی | F55: زارعی | G55: غفاری | M55: =SUMPRODUCT(H55:L55,$AA$2:$AE$2) -> 0
A56: 100 | B56: =VLOOKUP(C56,Sheet1!$A$2:$B$1132,2,FALSE) -> VITAL | C56: 0150RL01 | D56: رولر پرس | E56: مهدی زاده | F56: زارعی | G56: غفاری | H56: 1 | I56: 1 | J56: 1 | K56: 1 | L56: 1 | M56: =SUMPRODUCT(H56:L56,$AA$2:$AE$2) -> 1
...

Sheet متفرقه
A1: ناحیه | B1: درصد پیشرفت | C1: Main Asset | D1: AssetNumber | E1: وزن تجهیز در ناحیه | F1: Asset Tag No | G1: نام تجهیز | H1: کارشناس انجام دهنده مکانیک | I1: کارشناس انجام دهنده برق | J1: برگزاری جلسه مشترک و تهیه درخت روی وایت برد | K1: پیشرفت فایل اکسل مکانیک | L1: پیشرفت فایل اکسل برق | M1: کنترل فایل توسط CPG | N1: جمع بندی فایل اکسل نهایی | O1: درصد تکمیل فایل نهایی
A2: 1500 | F2: 1500.PI-CE01 | G2: HEAT TRACING | O2: 0
A3: 1500 | F3: 1510AC01 | G3: چیلر جذبی | H3: وشتانی | O3: 0
A4: 1500 | F4: 1510AC02 | G4: چیلر جذبی | H4: وشتانی | O4: 0
A5: 1500 | F5: 1510AH01 | G5: هواساز پست برق ساختمان بالینگ | H5: وشتانی | O5: 0
A6: 1500 | F6: 1510AH02 | G6: هواساز اداری ساختمان بالینگ | H6: وشتانی | O6: 0
A7: 1500 | F7: 1510DS01 | G7: سختی گیر موتورخانه بالینگ | H7: وشتانی | O7: 0
A8: 1500 | F8: 1510EC01 | G8: برج خنک کن چیلر موتورخانه بالینگ | H8: وشتانی | O8: 0
A9: 1500 | F9: 1510EC02 | G9: برج خنک کن چیلر موتورخانه بالینگ | H9: وشتانی | O9: 0
A10: 1500 | F10: 1510EF01 | G10: اگزاس فن | H10: وشتانی | O10: 0
A11: 1500 | F11: 1510LP01 | G11: پمپ خطی برگشتی موتورخانه بالینگ | H11: وشتانی | O11: 0
A12: 1500 | F12: 1510LP02 | G12: پمپ خطی برگشتی موتورخانه بالینگ | H12: وشتانی | O12: 0
A13: 1500 | F13: 1510LP03 | G13: پمپ خطی برگشتی موتورخانه بالینگ | H13: وشتانی | O13: 0
A14: 1500 | F14: 1510LP04 | G14: پمپ خطی برگشتی موتورخانه بالینگ | H14: وشتانی | O14: 0
A15: 1500 | F15: 1510OB01 | G15: ساختمان ترانسپورت | H15: 0 | O15: 0
A16: 1500 | F16: 1510WP01 | G16: واتر پمپ | H16: وشتانی | O16: 0
A17: 1500 | F17: 1510WP02 | G17: واتر پمپ | H17: وشتانی | O17: 0
A18: 1500 | F18: 1510WP03 | G18: واتر پمپ | H18: وشتانی | O18: 0
A19: 1500 | F19: 1510WP04 | G19: واتر پمپ | H19: وشتانی | O19: 0
A20: 1500 | F20: 1510WP05 | G20: واتر پمپ | H20: وشتانی | O20: 0
A21: 1500 | F21: 1510WP06 | G21: واتر پمپ | H21: وشتانی | O21: 0
A22: 1500 | F22: 1510WP07 | G22: واتر پمپ | H22: وشتانی | O22: 0
A23: 1500 | F23: 1520AC01 | G23: چیلر جذبی موتورخانه مرکزی | H23: وشتانی | O23: 0
A24: 1500 | F24: 1520AC02 | G24: چیلر جذبی موتورخانه مرکزی | H24: وشتانی | O24: 0
A25: 1500 | F25: 1520BH01 | G25: بویلر آب گرم فولادی | H25: وشتانی | O25: 0
A26: 1500 | F26: 1520BH02 | G26: بویلر آب گرم فولادی | H26: وشتانی | O26: 0
A27: 1500 | F27: 1520BH03 | G27: بویلر آب گرم فولادی | H27: وشتانی | O27: 0
... A76: 1500 | F76: 1580SH01 | G76: آبگرم کن خورشیدی | H76: پاک نیا | O76: 0
A77: 1500 | F77: 15902A01 | G77: UPS | O77: 0
A78: 1500 | F78: 1590CP01 | G78: کمپرسور هوا | H78: وشتانی | O78: 0
A79: 1500 | F79: 1590IP01 | G79: پمپ کف کش | H79: وشتانی | O79: 0
A80: 1500 | F80: 1590PI01 | G80: پایپینگ | H80: وشتانی | O80: 0
A81: 1500 | F81: 1590SU01 | G81: اسپلیت یونیت | H81: وشتانی | O81: 0
A82: 1500 | F82: 1590SU02 | G82: اسپلیت یونیت | H82: وشتانی | O82: 0
A83: 1500 | F83: 1590SU03 | G83: اسپلیت یونیت | H83: وشتانی | O83: 0
A84: 1500 | F84: 1590WP01 | G84: واتر پمپ | H84: وشتانی | O84: 0
A85: 1500 | F85: 1590WP02 | G85: واتر پمپ | H85: وشتانی | O85: 0
A86: 1500 | F86: 1590WP03 | G86: واتر پمپ | H86: وشتانی | O86: 0
A87: 1500 | F87: 1590WP04 | G87: واتر پمپ | H87: وشتانی | O87: 0
A88: 1500 | F88: 1590WP05 | G88: پمپ شناور چاه شماره یک | H88: وشتانی | O88: 0
...

Sheet Sheet1
A1: کد تجهیز | B1: الگو | C1: ردیف | D1: مقدار شاخص
A2: 0730AN01 | B2: VITAL | C2: 1 | D2: 8.47
A3: 0720BU01 | B3: VITAL | C3: 2 | D3: 7.884
A4: 0730FN01 | B4: VITAL | C4: 3 | D4: 7.647
A5: 0730FN02 | B5: VITAL | C5: 4 | D5: 7.647
A6: 0710TG01 | B6: VITAL | C6: 5 | D6: 7.622
A7: 0720KL01 | B7: VITAL | C7: 6 | D7: 7.622
A8: 0710FN01 | B8: VITAL | C8: 7 | D8: 7.452
A9: 0710FN02 | B9: VITAL | C9: 8 | D9: 7.452
A10: 0710FN04 | B10: VITAL | C10: 9 | D10: 7.377
A11: 0710FN03 | B11: VITAL | C11: 10 | D11: 7.252
A12: 0710FN05 | B12: VITAL | C12: 11 | D12: 7.252
A13: 0710FN06 | B13: VITAL | C13: 12 | D13: 7.152
... A1074: D550 | B1074: NORMAL | C1074: 1073 | D1074: 1.86
A1075: 8217 | B1075: NORMAL | C1075: 1074 | D1075: 1.86
A1076: HP630D | B1076: NORMAL | C1076: 1075 | D1076: 1.86
A1077: MR 3002 | B1077: NORMAL | C1077: 1076 | D1077: 1.86
A1078: FTM-10 | B1078: NORMAL | C1078: 1077 | D1078: 1.86
A1079: MR 3002 | B1079: NORMAL | C1079: 1078 | D1079: 1.86
A1080: MS-H-S | B1080: NORMAL | C1080: 1079 | D1080: 1.86
A1081: ST11 | B1081: NORMAL | C1081: 1080 | D1081: 1.86
A1082: pH 197i | B1082: NORMAL | C1082: 1081 | D1082: 1.86
A1083: 827 pH lab | B1083: NORMAL | C1083: 1082 | D1083: 1.86
A1084: HQ40d | B1084: NORMAL | C1084: 1083 | D1084: 1.86
A1085: Cond7310 | B1085: NORMAL | C1085: 1084 | D1085: 1.86
A1086: PC Compact | B1086: NORMAL | C1086: 1085 | D1086: 1.86
A1087: PC compact | B1087: NORMAL | C1087: 1086 | D1087: 1.86
A1088: 2008 | B1088: NORMAL | C1088: 1087 | D1088: 1.86
A1089: RK100 | B1089: NORMAL | C1089: 1088 | D1089: 1.86
A1090: UR1 | B1090: NORMAL | C1090: 1089 | D1090: 1.86
A1091: PM4 | B1091: NORMAL | C1091: 1090 | D1091: 1.86
A1092: OSK-194 | B1092: NORMAL | C1092: 1091 | D1092: 1.86
A1093: ITB600 | B1093: NORMAL | C1093: 1092 | D1093: 1.86
A1094: GP 30 K | B1094: NORMAL | C1094: 1093 | D1094: 1.86
A1095: GF-3000 | B1095: NORMAL | C1095: 1094 | D1095: 1.86
A1096: FX-3000GD | B1096: NORMAL | C1096: 1095 | D1096: 1.86
A1097: GR200 | B1097: NORMAL | C1097: 1096 | D1097: 1.86
A1098: CPA 324 S | B1098: NORMAL | C1098: 1097 | D1098: 1.86
A1099: LP2200 | B1099: NORMAL | C1099: 1098 | D1099: 1.86
A1100: LP2200 | B1100: NORMAL | C1100: 1099 | D1100: 1.86
...
